Thu Jun 25 23:20:18 SGT 2020 : Apache Derby Network Server - 10.11.1.2 - (1629631) started and ready to accept connections on port 1527
----------------------------------------------------------------
Thu Jun 25 23:20:19 SGT 2020:
Booting Derby version The Apache Software Foundation - Apache Derby - 10.11.1.2 - (1629631): instance a816c00e-0172-ec10-a60e-ffffde35d73a 
on database directory C:\Users\USER\Desktop\SC Project 1\Library-Management-System-JAVA-master\Database\LMS with class loader sun.misc.Launcher$AppClassLoader@6f94fa3e 
Loaded from file:/C:/Program%20Files/Java/jdk1.8.0_111/db/lib/derby.jar
java.vendor=Oracle Corporation
java.runtime.version=1.8.0_111-b14
user.dir=C:\Program Files\Java\jdk1.8.0_111\db
os.name=Windows 10
os.arch=amd64
os.version=10.0
derby.system.home=C:\Users\USER\Desktop\SC Project 1\Library-Management-System-JAVA-master\Database
Database Class Loader started - derby.database.classpath=''
Thu Jun 25 23:20:19 SGT 2020 Thread[DRDAConnThread_2,5,main] (XID = 393), (SESSIONID = 0), (DATABASE = LMS), (DRDAID = {1}), Cleanup action starting
java.sql.SQLNonTransientConnectionException: Connection authentication failure occurred.  Reason: Invalid authentication..
	at org.apache.derby.impl.jdbc.SQLExceptionFactory.getSQLException(Unknown Source)
	at org.apache.derby.impl.jdbc.SQLExceptionFactory.getSQLException(Unknown Source)
	at org.apache.derby.impl.jdbc.Util.generateCsSQLException(Unknown Source)
	at org.apache.derby.impl.jdbc.Util.generateCsSQLException(Unknown Source)
	at org.apache.derby.impl.jdbc.EmbedConnection.newSQLException(Unknown Source)
	at org.apache.derby.impl.jdbc.EmbedConnection.checkUserCredentials(Unknown Source)
	at org.apache.derby.impl.jdbc.EmbedConnection.<init>(Unknown Source)
	at org.apache.derby.jdbc.InternalDriver.getNewEmbedConnection(Unknown Source)
	at org.apache.derby.jdbc.InternalDriver.connect(Unknown Source)
	at org.apache.derby.jdbc.InternalDriver.connect(Unknown Source)
	at org.apache.derby.jdbc.EmbeddedDriver.connect(Unknown Source)
	at org.apache.derby.impl.drda.Database.makeConnection(Unknown Source)
	at org.apache.derby.impl.drda.DRDAConnThread.getConnFromDatabaseName(Unknown Source)
	at org.apache.derby.impl.drda.DRDAConnThread.verifyUserIdPassword(Unknown Source)
	at org.apache.derby.impl.drda.DRDAConnThread.parseSECCHK(Unknown Source)
	at org.apache.derby.impl.drda.DRDAConnThread.parseDRDAConnection(Unknown Source)
	at org.apache.derby.impl.drda.DRDAConnThread.processCommands(Unknown Source)
	at org.apache.derby.impl.drda.DRDAConnThread.run(Unknown Source)
Caused by: ERROR 08004: Connection authentication failure occurred.  Reason: Invalid authentication..
	at org.apache.derby.iapi.error.StandardException.newException(Unknown Source)
	at org.apache.derby.impl.jdbc.SQLExceptionFactory.wrapArgsForTransportAcrossDRDA(Unknown Source)
	... 18 more
============= begin nested exception, level (1) ===========
ERROR 08004: Connection authentication failure occurred.  Reason: Invalid authentication..
	at org.apache.derby.iapi.error.StandardException.newException(Unknown Source)
	at org.apache.derby.impl.jdbc.SQLExceptionFactory.wrapArgsForTransportAcrossDRDA(Unknown Source)
	at org.apache.derby.impl.jdbc.SQLExceptionFactory.getSQLException(Unknown Source)
	at org.apache.derby.impl.jdbc.SQLExceptionFactory.getSQLException(Unknown Source)
	at org.apache.derby.impl.jdbc.Util.generateCsSQLException(Unknown Source)
	at org.apache.derby.impl.jdbc.Util.generateCsSQLException(Unknown Source)
	at org.apache.derby.impl.jdbc.EmbedConnection.newSQLException(Unknown Source)
	at org.apache.derby.impl.jdbc.EmbedConnection.checkUserCredentials(Unknown Source)
	at org.apache.derby.impl.jdbc.EmbedConnection.<init>(Unknown Source)
	at org.apache.derby.jdbc.InternalDriver.getNewEmbedConnection(Unknown Source)
	at org.apache.derby.jdbc.InternalDriver.connect(Unknown Source)
	at org.apache.derby.jdbc.InternalDriver.connect(Unknown Source)
	at org.apache.derby.jdbc.EmbeddedDriver.connect(Unknown Source)
	at org.apache.derby.impl.drda.Database.makeConnection(Unknown Source)
	at org.apache.derby.impl.drda.DRDAConnThread.getConnFromDatabaseName(Unknown Source)
	at org.apache.derby.impl.drda.DRDAConnThread.verifyUserIdPassword(Unknown Source)
	at org.apache.derby.impl.drda.DRDAConnThread.parseSECCHK(Unknown Source)
	at org.apache.derby.impl.drda.DRDAConnThread.parseDRDAConnection(Unknown Source)
	at org.apache.derby.impl.drda.DRDAConnThread.processCommands(Unknown Source)
	at org.apache.derby.impl.drda.DRDAConnThread.run(Unknown Source)
============= end nested exception, level (1) ===========
Cleanup action completed
Thu Jun 25 23:20:19 SGT 2020 Thread[DRDAConnThread_2,5,main] (DATABASE = LMS), (DRDAID = {1}), Connection authentication failure occurred.  Reason: Invalid authentication..
Fri Jun 26 14:13:39 SGT 2020 Thread[DRDAConnThread_5,5,main] (XID = 574), (SESSIONID = 15), (DATABASE = LMS), (DRDAID = {9}), Cleanup action starting
java.sql.SQLNonTransientConnectionException: Connection authentication failure occurred.  Reason: Invalid authentication..
	at org.apache.derby.impl.jdbc.SQLExceptionFactory.getSQLException(Unknown Source)
	at org.apache.derby.impl.jdbc.SQLExceptionFactory.getSQLException(Unknown Source)
	at org.apache.derby.impl.jdbc.Util.generateCsSQLException(Unknown Source)
	at org.apache.derby.impl.jdbc.Util.generateCsSQLException(Unknown Source)
	at org.apache.derby.impl.jdbc.EmbedConnection.newSQLException(Unknown Source)
	at org.apache.derby.impl.jdbc.EmbedConnection.checkUserCredentials(Unknown Source)
	at org.apache.derby.impl.jdbc.EmbedConnection.<init>(Unknown Source)
	at org.apache.derby.jdbc.InternalDriver.getNewEmbedConnection(Unknown Source)
	at org.apache.derby.jdbc.InternalDriver.connect(Unknown Source)
	at org.apache.derby.jdbc.InternalDriver.connect(Unknown Source)
	at org.apache.derby.jdbc.EmbeddedDriver.connect(Unknown Source)
	at org.apache.derby.impl.drda.Database.makeConnection(Unknown Source)
	at org.apache.derby.impl.drda.DRDAConnThread.getConnFromDatabaseName(Unknown Source)
	at org.apache.derby.impl.drda.DRDAConnThread.verifyUserIdPassword(Unknown Source)
	at org.apache.derby.impl.drda.DRDAConnThread.parseSECCHK(Unknown Source)
	at org.apache.derby.impl.drda.DRDAConnThread.parseDRDAConnection(Unknown Source)
	at org.apache.derby.impl.drda.DRDAConnThread.processCommands(Unknown Source)
	at org.apache.derby.impl.drda.DRDAConnThread.run(Unknown Source)
Caused by: ERROR 08004: Connection authentication failure occurred.  Reason: Invalid authentication..
	at org.apache.derby.iapi.error.StandardException.newException(Unknown Source)
	at org.apache.derby.impl.jdbc.SQLExceptionFactory.wrapArgsForTransportAcrossDRDA(Unknown Source)
	... 18 more
============= begin nested exception, level (1) ===========
ERROR 08004: Connection authentication failure occurred.  Reason: Invalid authentication..
	at org.apache.derby.iapi.error.StandardException.newException(Unknown Source)
	at org.apache.derby.impl.jdbc.SQLExceptionFactory.wrapArgsForTransportAcrossDRDA(Unknown Source)
	at org.apache.derby.impl.jdbc.SQLExceptionFactory.getSQLException(Unknown Source)
	at org.apache.derby.impl.jdbc.SQLExceptionFactory.getSQLException(Unknown Source)
	at org.apache.derby.impl.jdbc.Util.generateCsSQLException(Unknown Source)
	at org.apache.derby.impl.jdbc.Util.generateCsSQLException(Unknown Source)
	at org.apache.derby.impl.jdbc.EmbedConnection.newSQLException(Unknown Source)
	at org.apache.derby.impl.jdbc.EmbedConnection.checkUserCredentials(Unknown Source)
	at org.apache.derby.impl.jdbc.EmbedConnection.<init>(Unknown Source)
	at org.apache.derby.jdbc.InternalDriver.getNewEmbedConnection(Unknown Source)
	at org.apache.derby.jdbc.InternalDriver.connect(Unknown Source)
	at org.apache.derby.jdbc.InternalDriver.connect(Unknown Source)
	at org.apache.derby.jdbc.EmbeddedDriver.connect(Unknown Source)
	at org.apache.derby.impl.drda.Database.makeConnection(Unknown Source)
	at org.apache.derby.impl.drda.DRDAConnThread.getConnFromDatabaseName(Unknown Source)
	at org.apache.derby.impl.drda.DRDAConnThread.verifyUserIdPassword(Unknown Source)
	at org.apache.derby.impl.drda.DRDAConnThread.parseSECCHK(Unknown Source)
	at org.apache.derby.impl.drda.DRDAConnThread.parseDRDAConnection(Unknown Source)
	at org.apache.derby.impl.drda.DRDAConnThread.processCommands(Unknown Source)
	at org.apache.derby.impl.drda.DRDAConnThread.run(Unknown Source)
============= end nested exception, level (1) ===========
Cleanup action completed
Fri Jun 26 14:13:39 SGT 2020 Thread[DRDAConnThread_5,5,main] (DATABASE = LMS), (DRDAID = {9}), Connection authentication failure occurred.  Reason: Invalid authentication..
Fri Jun 26 15:00:02 SGT 2020 Thread[DRDAConnThread_4,5,main] (XID = 590), (SESSIONID = 20), (DATABASE = LMS), (DRDAID = {12}), Cleanup action starting
java.sql.SQLNonTransientConnectionException: Connection authentication failure occurred.  Reason: Invalid authentication..
	at org.apache.derby.impl.jdbc.SQLExceptionFactory.getSQLException(Unknown Source)
	at org.apache.derby.impl.jdbc.SQLExceptionFactory.getSQLException(Unknown Source)
	at org.apache.derby.impl.jdbc.Util.generateCsSQLException(Unknown Source)
	at org.apache.derby.impl.jdbc.Util.generateCsSQLException(Unknown Source)
	at org.apache.derby.impl.jdbc.EmbedConnection.newSQLException(Unknown Source)
	at org.apache.derby.impl.jdbc.EmbedConnection.checkUserCredentials(Unknown Source)
	at org.apache.derby.impl.jdbc.EmbedConnection.<init>(Unknown Source)
	at org.apache.derby.jdbc.InternalDriver.getNewEmbedConnection(Unknown Source)
	at org.apache.derby.jdbc.InternalDriver.connect(Unknown Source)
	at org.apache.derby.jdbc.InternalDriver.connect(Unknown Source)
	at org.apache.derby.jdbc.EmbeddedDriver.connect(Unknown Source)
	at org.apache.derby.impl.drda.Database.makeConnection(Unknown Source)
	at org.apache.derby.impl.drda.DRDAConnThread.getConnFromDatabaseName(Unknown Source)
	at org.apache.derby.impl.drda.DRDAConnThread.verifyUserIdPassword(Unknown Source)
	at org.apache.derby.impl.drda.DRDAConnThread.parseSECCHK(Unknown Source)
	at org.apache.derby.impl.drda.DRDAConnThread.parseDRDAConnection(Unknown Source)
	at org.apache.derby.impl.drda.DRDAConnThread.processCommands(Unknown Source)
	at org.apache.derby.impl.drda.DRDAConnThread.run(Unknown Source)
Caused by: ERROR 08004: Connection authentication failure occurred.  Reason: Invalid authentication..
	at org.apache.derby.iapi.error.StandardException.newException(Unknown Source)
	at org.apache.derby.impl.jdbc.SQLExceptionFactory.wrapArgsForTransportAcrossDRDA(Unknown Source)
	... 18 more
============= begin nested exception, level (1) ===========
ERROR 08004: Connection authentication failure occurred.  Reason: Invalid authentication..
	at org.apache.derby.iapi.error.StandardException.newException(Unknown Source)
	at org.apache.derby.impl.jdbc.SQLExceptionFactory.wrapArgsForTransportAcrossDRDA(Unknown Source)
	at org.apache.derby.impl.jdbc.SQLExceptionFactory.getSQLException(Unknown Source)
	at org.apache.derby.impl.jdbc.SQLExceptionFactory.getSQLException(Unknown Source)
	at org.apache.derby.impl.jdbc.Util.generateCsSQLException(Unknown Source)
	at org.apache.derby.impl.jdbc.Util.generateCsSQLException(Unknown Source)
	at org.apache.derby.impl.jdbc.EmbedConnection.newSQLException(Unknown Source)
	at org.apache.derby.impl.jdbc.EmbedConnection.checkUserCredentials(Unknown Source)
	at org.apache.derby.impl.jdbc.EmbedConnection.<init>(Unknown Source)
	at org.apache.derby.jdbc.InternalDriver.getNewEmbedConnection(Unknown Source)
	at org.apache.derby.jdbc.InternalDriver.connect(Unknown Source)
	at org.apache.derby.jdbc.InternalDriver.connect(Unknown Source)
	at org.apache.derby.jdbc.EmbeddedDriver.connect(Unknown Source)
	at org.apache.derby.impl.drda.Database.makeConnection(Unknown Source)
	at org.apache.derby.impl.drda.DRDAConnThread.getConnFromDatabaseName(Unknown Source)
	at org.apache.derby.impl.drda.DRDAConnThread.verifyUserIdPassword(Unknown Source)
	at org.apache.derby.impl.drda.DRDAConnThread.parseSECCHK(Unknown Source)
	at org.apache.derby.impl.drda.DRDAConnThread.parseDRDAConnection(Unknown Source)
	at org.apache.derby.impl.drda.DRDAConnThread.processCommands(Unknown Source)
	at org.apache.derby.impl.drda.DRDAConnThread.run(Unknown Source)
============= end nested exception, level (1) ===========
Cleanup action completed
Fri Jun 26 15:00:02 SGT 2020 Thread[DRDAConnThread_4,5,main] (DATABASE = LMS), (DRDAID = {12}), Connection authentication failure occurred.  Reason: Invalid authentication..
